Workbook

Sheet statushistory
A1: Status Id | B1: Control Sense Id | C1: Id status main | D1: Id status type | E1: Id status detail | F1: Id equipment | G1: Id employee | H1: Inicio de estado | I1: Fin de estado | J1: Date cube | K1: Duración Hr. | L1: Hour | M1: numer | P1: Equipment | Q1: Equipment - ID
A2: 466083 | B2: 466083 | C2: 1 | D2: 6 | E2: 2404 | F2: 84 | G2: 138 | H2: 2025-09-01 07:00:37.759205 | I2: 2025-09-01 10:14:30.298 | J2: 45901 | K2: 3.23126077638889 | L2: 7 | M2: =_xlfn.NUMBERVALUE("" & K2 & "",".",",") -> 3.2312608 | N2: =SUM(M:M) -> 2290.8832 | O2: =VLOOKUP(C2,statusdetails!$A:$D,4,0) -> READY | P2: =VLOOKUP(F2,equipment!$A:$E,4,0) -> CM01 | Q2: =VLOOKUP(F2,equipment!$A:$E,5,0) -> CM01 - 84
A3: 466084 | B3: 466084 | C3: 1 | D3: 6 | E3: 260 | F3: 34 | G3: 85 | H3: 2025-09-01 07:02:40.895 | I3: 2025-09-01 07:52:58.07474 | J3: 45901 | K3: 0.838105483333333 | L3: 7 | M3: =_xlfn.NUMBERVALUE("" & K3 & "",".",",") -> 0.83810548 | N3: =COUNT(M:M) -> 1296 | O3: =VLOOKUP(C3,statusdetails!$A:$D,4,0) -> READY | P3: =VLOOKUP(F3,equipment!$A:$E,4,0) -> CM404 | Q3: =VLOOKUP(F3,equipment!$A:$E,5,0) -> CM404 - 34
A4: 466085 | B4: 466085 | C4: 1 | D4: 6 | E4: 372 | F4: 91 | G4: 64 | H4: 2025-09-01 07:03:33.865206 | I4: 2025-09-01 07:20:20.29575 | J4: 45901 | K4: 0.27956404 | L4: 7 | M4: =_xlfn.NUMBERVALUE("" & K4 & "",".",",") -> 0.27956404 | O4: =VLOOKUP(C4,statusdetails!$A:$D,4,0) -> READY | P4: =VLOOKUP(F4,equipment!$A:$E,4,0) -> DZ205 | Q4: =VLOOKUP(F4,equipment!$A:$E,5,0) -> DZ205 - 91
A5: 466086 | B5: 466086 | C5: 1 | D5: 6 | E5: 586 | F5: 41 | G5: 126 | H5: 2025-09-01 07:03:38.214362 | I5: 2025-09-01 11:00:32.97469 | J5: 45901 | K5: 3.94854453555556 | L5: 7 | M5: =_xlfn.NUMBERVALUE("" & K5 & "",".",",") -> 3.9485445 | O5: =VLOOKUP(C5,statusdetails!$A:$D,4,0) -> READY | P5: =VLOOKUP(F5,equipment!$A:$E,4,0) -> MO102 | Q5: =VLOOKUP(F5,equipment!$A:$E,5,0) -> MO102 - 41
A6: 466087 | B6: 466087 | C6: 1 | D6: 6 | E6: 2524 | F6: 74 | G6: 0 | H6: 2025-09-01 07:03:44.313648 | I6: 2025-09-01 12:04:54.827478 | J6: 45901 | K6: 5.019587175 | L6: 7 | M6: =_xlfn.NUMBERVALUE("" & K6 & "",".",",") -> 5.0195872 | O6: =VLOOKUP(C6,statusdetails!$A:$D,4,0) -> READY | P6: =VLOOKUP(F6,equipment!$A:$E,4,0) -> CR701 | Q6: =VLOOKUP(F6,equipment!$A:$E,5,0) -> CR701 - 74
A7: 466088 | B7: 466088 | C7: 4 | D7: 15 | E7: 1778 | F7: 91 | G7: 64 | H7: 2025-09-01 07:20:20.29575 | I7: 2025-09-01 10:58:23.890894 | J7: 45901 | K7: 3.63433198444444 | L7: 7 | M7: =_xlfn.NUMBERVALUE("" & K7 & "",".",",") -> 3.634332 | N7: =SUM(M:M) -> 2290.8832 | O7: =VLOOKUP(C7,statusdetails!$A:$D,4,0) -> MAINT | P7: =VLOOKUP(F7,equipment!$A:$E,4,0) -> DZ205 | Q7: =VLOOKUP(F7,equipment!$A:$E,5,0) -> DZ205 - 91
A8: 466089 | B8: 466089 | C8: 1 | D8: 6 | E8: 372 | F8: 37 | G8: 74 | H8: 2025-09-01 07:20:40.145 | I8: 2025-09-01 11:48:31.517448 | J8: 45901 | K8: 4.46427012444444 | L8: 7 | M8: =_xlfn.NUMBERVALUE("" & K8 & "",".",",") -> 4.4642701 | O8: =VLOOKUP(C8,statusdetails!$A:$D,4,0) -> READY | P8: =VLOOKUP(F8,equipment!$A:$E,4,0) -> DZ201 | Q8: =VLOOKUP(F8,equipment!$A:$E,5,0) -> DZ201 - 37
A9: 466090 | B9: 466090 | C9: 2 | D9: 7 | E9: 821 | F9: 42 | G9: 5 | H9: 2025-09-01 07:22:42.637 | I9: 2025-09-01 07:31:28.498 | J9: 45901 | K9: 0.1460725 | L9: 7 | M9: =_xlfn.NUMBERVALUE("" & K9 & "",".",",") -> 0.1460725 | N9: =SUM(M:M) -> 2290.8832 | O9: =VLOOKUP(C9,statusdetails!$A:$D,4,0) -> DELAY | P9: =VLOOKUP(F9,equipment!$A:$E,4,0) -> PE301 | Q9: =VLOOKUP(F9,equipment!$A:$E,5,0) -> PE301 - 42
A10: 466091 | B10: 466091 | C10: 1 | D10: 6 | E10: 811 | F10: 42 | G10: 5 | H10: 2025-09-01 07:31:28.498 | I10: 2025-09-01 08:30:05.999 | J10: 45901 | K10: 0.977083611111111 | L10: 7 | M10: =_xlfn.NUMBERVALUE("" & K10 & "",".",",") -> 0.97708361 | O10: =VLOOKUP(C10,statusdetails!$A:$D,4,0) -> READY | P10: =VLOOKUP(F10,equipment!$A:$E,4,0) -> PE301 | Q10: =VLOOKUP(F10,equipment!$A:$E,5,0) -> PE301 - 42
A11: 466092 | B11: 466092 | C11: 4 | D11: 16 | E11: 368 | F11: 34 | G11: 119 | H11: 2025-09-01 07:52:58.07474 | I11: 2025-09-01 07:55:25.29294 | J11: 45901 | K11: 0.0408939444444444 | L11: 7 | M11: =_xlfn.NUMBERVALUE("" & K11 & "",".",",") -> 0.040893944 | N11: =COUNT(M:M) -> 1296 | O11: =VLOOKUP(C11,statusdetails!$A:$D,4,0) -> MAINT | P11: =VLOOKUP(F11,equipment!$A:$E,4,0) -> CM404 | Q11: =VLOOKUP(F11,equipment!$A:$E,5,0) -> CM404 - 34
A12: 466093 | B12: 466093 | C12: 1 | D12: 6 | E12: 260 | F12: 34 | G12: 119 | H12: 2025-09-01 07:55:25.29294 | I12: 2025-09-01 07:58:18.016878 | J12: 45901 | K12: 0.0479788716666667 | L12: 7 | M12: =_xlfn.NUMBERVALUE("" & K12 & "",".",",") -> 0.047978872 | O12: =VLOOKUP(C12,statusdetails!$A:$D,4,0) -> READY | P12: =VLOOKUP(F12,equipment!$A:$E,4,0) -> CM404 | Q12: =VLOOKUP(F12,equipment!$A:$E,5,0) -> CM404 - 34
A13: 466094 | B13: 466094 | C13: 4 | D13: 16 | E13: 368 | F13: 34 | G13: 119 | H13: 2025-09-01 07:58:18.016878 | I13: 2025-09-01 08:37:37.843106 | J13: 45901 | K13: 0.655507285555555 | L13: 7 | M13: =_xlfn.NUMBERVALUE("" & K13 & "",".",",") -> 0.65550729 | O13: =VLOOKUP(C13,statusdetails!$A:$D,4,0) -> MAINT | P13: =VLOOKUP(F13,equipment!$A:$E,4,0) -> CM404 | Q13: =VLOOKUP(F13,equipment!$A:$E,5,0) -> CM404 - 34
A14: 466095 | B14: 466095 | C14: 4 | D14: 16 | E14: 2459 | F14: 86 | G14: 142 | H14: 2025-09-01 08:03:53.598497 | I14: 2025-09-01 18:24:57.616487 | J14: 45901 | K14: 10.3511161083333 | L14: 8 | M14: =_xlfn.NUMBERVALUE("" & K14 & "",".",",") -> 10.351116 | O14: =VLOOKUP(C14,statusdetails!$A:$D,4,0) -> MAINT | P14: =VLOOKUP(F14,equipment!$A:$E,4,0) -> CM03 | Q14: =VLOOKUP(F14,equipment!$A:$E,5,0) -> CM03 - 86
A15: 466096 | B15: 466096 | C15: 3 | D15: 12 | E15: 1012 | F15: 42 | G15: 5 | H15: 2025-09-01 08:30:05.999 | I15: 2025-09-01 17:55:05.29 | J15: 45901 | K15: 9.41646972222222 | L15: 8 | M15: =_xlfn.NUMBERVALUE("" & K15 & "",".",",") -> 9.4164697 | N15: =SUM(M:M) -> 2290.8832 | O15: =VLOOKUP(C15,statusdetails!$A:$D,4,0) -> STANDBY | P15: =VLOOKUP(F15,equipment!$A:$E,4,0) -> PE301 | Q15: =VLOOKUP(F15,equipment!$A:$E,5,0) -> PE301 - 42
A16: 466097 | B16: 466097 | C16: 4 | D16: 16 | E16: 966 | F16: 34 | G16: 119 | H16: 2025-09-01 08:37:37.843106 | I16: 2025-09-01 14:20:36.114532 | J16: 45901 | K16: 5.71618650722222 | L16: 8 | M16: =_xlfn.NUMBERVALUE("" & K16 & "",".",",") -> 5.7161865 | O16: =VLOOKUP(C16,statusdetails!$A:$D,4,0) -> MAINT | P16: =VLOOKUP(F16,equipment!$A:$E,4,0) -> CM404 | Q16: =VLOOKUP(F16,equipment!$A:$E,5,0) -> CM404 - 34
A17: 466098 | B17: 466098 | C17: 1 | D17: 6 | E17: 811 | F17: 43 | G17: 5 | H17: 2025-09-01 08:38:40.069329 | I17: 2025-09-01 09:26:52.470485 | J17: 45901 | K17: 0.803444765555556 | L17: 8 | M17: =_xlfn.NUMBERVALUE("" & K17 & "",".",",") -> 0.80344477 | O17: =VLOOKUP(C17,statusdetails!$A:$D,4,0) -> READY | P17: =VLOOKUP(F17,equipment!$A:$E,4,0) -> PE302 | Q17: =VLOOKUP(F17,equipment!$A:$E,5,0) -> PE302 - 43
A18: 466099 | B18: 466099 | C18: 4 | D18: 15 | E18: 1777 | F18: 49 | G18: 0 | H18: 2025-09-01 08:47:07.992833 | I18: 2025-09-01 13:07:05.66072 | J18: 45901 | K18: 4.33268552416667 | L18: 8 | M18: =_xlfn.NUMBERVALUE("" & K18 & "",".",",") -> 4.3326855 | O18: =VLOOKUP(C18,statusdetails!$A:$D,4,0) -> MAINT | P18: =VLOOKUP(F18,equipment!$A:$E,4,0) -> CR702 | Q18: =VLOOKUP(F18,equipment!$A:$E,5,0) -> CR702 - 49
A19: 466100 | B19: 466100 | C19: 2 | D19: 7 | E19: 1494 | F19: 60 | G19: 164 | H19: 2025-09-01 08:55:36.409119 | I19: 2025-09-01 09:05:43.779878 | J19: 45901 | K19: 0.168714099722222 | L19: 8 | M19: =_xlfn.NUMBERVALUE("" & K19 & "",".",",") -> 0.1687141 | N19: =COUNT(M:M) -> 1296 | O19: =VLOOKUP(C19,statusdetails!$A:$D,4,0) -> DELAY | P19: =VLOOKUP(F19,equipment!$A:$E,4,0) -> EX802 | Q19: =VLOOKUP(F19,equipment!$A:$E,5,0) -> EX802 - 60
A20: 466101 | B20: 466101 | C20: 2 | D20: 7 | E20: 1026 | F20: 32 | G20: 113 | H20: 2025-09-01 08:57:21.244 | I20: 2025-09-01 09:05:20.557 | J20: 45901 | K20: 0.1331425 | L20: 8 | M20: =_xlfn.NUMBERVALUE("" & K20 & "",".",",") -> 0.1331425 | O20: =VLOOKUP(C20,statusdetails!$A:$D,4,0) -> DELAY | P20: =VLOOKUP(F20,equipment!$A:$E,4,0) -> CM403 | Q20: =VLOOKUP(F20,equipment!$A:$E,5,0) -> CM403 - 32
A21: 466102 | B21: 466102 | C21: 1 | D21: 6 | E21: 260 | F21: 32 | G21: 113 | H21: 2025-09-01 09:05:20.557 | I21: 2025-09-01 10:40:14.581532 | J21: 45901 | K21: 1.58167348111111 | L21: 9 | M21: =_xlfn.NUMBERVALUE("" & K21 & "",".",",") -> 1.5816735 | O21: =VLOOKUP(C21,statusdetails!$A:$D,4,0) -> READY | P21: =VLOOKUP(F21,equipment!$A:$E,4,0) -> CM403 | Q21: =VLOOKUP(F21,equipment!$A:$E,5,0) -> CM403 - 32
A22: 466103 | B22: 466103 | C22: 1 | D22: 6 | E22: 1397 | F22: 60 | G22: 164 | H22: 2025-09-01 09:05:43.779878 | I22: 2025-09-01 10:37:26.129016 | J22: 45901 | K22: 1.52843031611111 | L22: 9 | M22: =_xlfn.NUMBERVALUE("" & K22 & "",".",",") -> 1.5284303 | O22: =VLOOKUP(C22,statusdetails!$A:$D,4,0) -> READY | P22: =VLOOKUP(F22,equipment!$A:$E,4,0) -> EX802 | Q22: =VLOOKUP(F22,equipment!$A:$E,5,0) -> EX802 - 60
A23: 466104 | B23: 466104 | C23: 2 | D23: 7 | E23: 815 | F23: 43 | G23: 5 | H23: 2025-09-01 09:26:52.470485 | I23: 2025-09-01 09:37:40.17 | J23: 45901 | K23: 0.179916531944444 | L23: 9 | M23: =_xlfn.NUMBERVALUE("" & K23 & "",".",",") -> 0.17991653 | O23: =VLOOKUP(C23,statusdetails!$A:$D,4,0) -> DELAY | P23: =VLOOKUP(F23,equipment!$A:$E,4,0) -> PE302 | Q23: =VLOOKUP(F23,equipment!$A:$E,5,0) -> PE302 - 43
A24: 466105 | B24: 466105 | C24: 1 | D24: 6 | E24: 811 | F24: 43 | G24: 5 | H24: 2025-09-01 09:37:40.17 | I24: 2025-09-01 11:06:45.405098 | J24: 45901 | K24: 1.48478752722222 | L24: 9 | M24: =_xlfn.NUMBERVALUE("" & K24 & "",".",",") -> 1.4847875 | O24: =VLOOKUP(C24,statusdetails!$A:$D,4,0) -> READY | P24: =VLOOKUP(F24,equipment!$A:$E,4,0) -> PE302 | Q24: =VLOOKUP(F24,equipment!$A:$E,5,0) -> PE302 - 43
A25: 466106 | B25: 466106 | C25: 2 | D25: 9 | E25: 2515 | F25: 85 | G25: 22 | H25: 2025-09-01 10:07:35.386599 | I25: 2025-09-01 10:09:00.038 | J25: 45901 | K25: 0.0235142780555556 | L25: 10 | M25: =_xlfn.NUMBERVALUE("" & K25 & "",".",",") -> 0.023514278 | O25: =VLOOKUP(C25,statusdetails!$A:$D,4,0) -> DELAY | P25: =VLOOKUP(F25,equipment!$A:$E,4,0) -> CM02 | Q25: =VLOOKUP(F25,equipment!$A:$E,5,0) -> CM02 - 85
A26: 466107 | B26: 466107 | C26: 1 | D26: 6 | E26: 2404 | F26: 85 | G26: 22 | H26: 2025-09-01 10:09:00.038 | I26: 2025-09-01 11:29:03.857527 | J26: 45901 | K26: 1.33439431305556 | L26: 10 | M26: =_xlfn.NUMBERVALUE("" & K26 & "",".",",") -> 1.3343943 | O26: =VLOOKUP(C26,statusdetails!$A:$D,4,0) -> READY | P26: =VLOOKUP(F26,equipment!$A:$E,4,0) -> CM02 | Q26: =VLOOKUP(F26,equipment!$A:$E,5,0) -> CM02 - 85
A27: 466108 | B27: 466108 | C27: 2 | D27: 9 | E27: 2512 | F27: 84 | G27: 138 | H27: 2025-09-01 10:14:30.298 | I27: 2025-09-01 10:22:57.193 | J27: 45901 | K27: 0.140804166666667 | L27: 10 | M27: =_xlfn.NUMBERVALUE("" & K27 & "",".",",") -> 0.14080417 | O27: =VLOOKUP(C27,statusdetails!$A:$D,4,0) -> DELAY | P27: =VLOOKUP(F27,equipment!$A:$E,4,0) -> CM01 | Q27: =VLOOKUP(F27,equipment!$A:$E,5,0) -> CM01 - 84
A28: 466109 | B28: 466109 | C28: 2 | D28: 9 | E28: 1059 | F28: 35 | G28: 78 | H28: 2025-09-01 10:18:03.522 | I28: 2025-09-01 10:20:13.131651 | J28: 45901 | K28: 0.0360026808333333 | L28: 10 | M28: =_xlfn.NUMBERVALUE("" & K28 & "",".",",") -> 0.036002681 | O28: =VLOOKUP(C28,statusdetails!$A:$D,4,0) -> DELAY | P28: =VLOOKUP(F28,equipment!$A:$E,4,0) -> CM405 | Q28: =VLOOKUP(F28,equipment!$A:$E,5,0) -> CM405 - 35
A29: 466110 | B29: 466110 | C29: 1 | D29: 6 | E29: 260 | F29: 35 | G29: 78 | H29: 2025-09-01 10:20:13.131651 | I29: 2025-09-01 12:08:45.20194 | J29: 45901 | K29: 1.80890841361111 | L29: 10 | M29: =_xlfn.NUMBERVALUE("" & K29 & "",".",",") -> 1.8089084 | O29: =VLOOKUP(C29,statusdetails!$A:$D,4,0) -> READY | P29: =VLOOKUP(F29,equipment!$A:$E,4,0) -> CM405 | Q29: =VLOOKUP(F29,equipment!$A:$E,5,0) -> CM405 - 35
A30: 466111 | B30: 466111 | C30: 1 | D30: 6 | E30: 2404 | F30: 84 | G30: 138 | H30: 2025-09-01 10:22:57.193 | I30: 2025-09-01 12:03:01.5671 | J30: 45901 | K30: 1.66788169444444 | L30: 10 | M30: =_xlfn.NUMBERVALUE("" & K30 & "",".",",") -> 1.6678817 | O30: =VLOOKUP(C30,statusdetails!$A:$D,4,0) -> READY | P30: =VLOOKUP(F30,equipment!$A:$E,4,0) -> CM01 | Q30: =VLOOKUP(F30,equipment!$A:$E,5,0) -> CM01 - 84
A31: 466112 | B31: 466112 | C31: 2 | D31: 7 | E31: 1494 | F31: 60 | G31: 164 | H31: 2025-09-01 10:37:26.129016 | I31: 2025-09-01 10:50:02.482 | J31: 45901 | K31: 0.210098051111111 | L31: 10 | M31: =_xlfn.NUMBERVALUE("" & K31 & "",".",",") -> 0.21009805 | O31: =VLOOKUP(C31,statusdetails!$A:$D,4,0) -> DELAY | P31: =VLOOKUP(F31,equipment!$A:$E,4,0) -> EX802 | Q31: =VLOOKUP(F31,equipment!$A:$E,5,0) -> EX802 - 60
... A40: 466121 | B40: 466121 | C40: 1 | D40: 6 | E40: 260 | F40: 66 | G40: 94 | H40: 2025-09-01 10:56:38.923 | I40: 2025-09-01 11:55:22.401 | J40: 45901 | K40: 0.978743888888889 | L40: 10 | M40: =_xlfn.NUMBERVALUE("" & K40 & "",".",",") -> 0.97874389 | O40: =VLOOKUP(C40,statusdetails!$A:$D,4,0) -> READY | P40: =VLOOKUP(F40,equipment!$A:$E,4,0) -> CM407 | Q40: =VLOOKUP(F40,equipment!$A:$E,5,0) -> CM407 - 66
A41: 466122 | B41: 466122 | C41: 3 | D41: 12 | E41: 394 | F41: 91 | G41: 64 | H41: 2025-09-01 10:58:23.890894 | I41: 2025-09-01 11:48:35.428759 | J41: 45901 | K41: 0.836538295833333 | L41: 10 | M41: =_xlfn.NUMBERVALUE("" & K41 & "",".",",") -> 0.8365383 | N41: =COUNT(M:M) -> 1296 | O41: =VLOOKUP(C41,statusdetails!$A:$D,4,0) -> STANDBY | P41: =VLOOKUP(F41,equipment!$A:$E,4,0) -> DZ205 | Q41: =VLOOKUP(F41,equipment!$A:$E,5,0) -> DZ205 - 91
A42: 466123 | B42: 466123 | C42: 4 | D42: 15 | E42: 630 | F42: 41 | G42: 126 | H42: 2025-09-01 11:00:32.97469 | I42: 2025-09-01 11:37:52.237954 | J42: 45901 | K42: 0.622017573333333 | L42: 11 | M42: =_xlfn.NUMBERVALUE("" & K42 & "",".",",") -> 0.62201757 | O42: =VLOOKUP(C42,statusdetails!$A:$D,4,0) -> MAINT
A43: 466124 | B43: 466124 | C43: 3 | D43: 12 | E43: 1012 | F43: 43 | G43: 5 | H43: 2025-09-01 11:06:45.405098 | I43: 2025-09-02 10:27:12.998113 | J43: 45901 | K43: 23.3409980597222 | L43: 11 | M43: =_xlfn.NUMBERVALUE("" & K43 & "",".",",") -> 23.340998 | O43: =VLOOKUP(C43,statusdetails!$A:$D,4,0) -> STANDBY | P43: =VLOOKUP(F43,equipment!$A:$E,4,0) -> PE302 | Q43: =VLOOKUP(F43,equipment!$A:$E,5,0) -> PE302 - 43
A44: 466125 | B44: 466125 | C44: 4 | D44: 15 | E44: 2396 | F44: 82 | G44: 110 | H44: 2025-09-01 11:28:21.017261 | I44: 2025-09-01 13:06:48.334108 | J44: 45901 | K44: 1.64092134638889 | L44: 11 | M44: =_xlfn.NUMBERVALUE("" & K44 & "",".",",") -> 1.6409213 | O44: =VLOOKUP(C44,statusdetails!$A:$D,4,0) -> MAINT
A45: 466126 | B45: 466126 | C45: 3 | D45: 12 | E45: 2422 | F45: 85 | G45: 22 | H45: 2025-09-01 11:29:03.857527 | I45: 2025-09-01 13:30:36.667307 | J45: 45901 | K45: 2.02578049444444 | L45: 11 | M45: =_xlfn.NUMBERVALUE("" & K45 & "",".",",") -> 2.0257805 | O45: =VLOOKUP(C45,statusdetails!$A:$D,4,0) -> STANDBY | P45: =VLOOKUP(F45,equipment!$A:$E,4,0) -> CM02 | Q45: =VLOOKUP(F45,equipment!$A:$E,5,0) -> CM02 - 85
A46: 466127 | B46: 466127 | C46: 3 | D46: 14 | E46: 2555 | F46: 88 | G46: 129 | H46: 2025-09-01 11:31:17.311 | I46: 2025-09-01 11:37:40.326015 | J46: 45901 | K46: 0.106393059722222 | L46: 11 | M46: =_xlfn.NUMBERVALUE("" & K46 & "",".",",") -> 0.10639306 | O46: =VLOOKUP(C46,statusdetails!$A:$D,4,0) -> STANDBY | P46: =VLOOKUP(F46,equipment!$A:$E,4,0) -> CM05 | Q46: =VLOOKUP(F46,equipment!$A:$E,5,0) -> CM05 - 88
A47: 466128 | B47: 466128 | C47: 3 | D47: 12 | E47: 2422 | F47: 88 | G47: 129 | H47: 2025-09-01 11:37:40.326015 | I47: 2025-09-01 13:30:44.163315 | J47: 45901 | K47: 1.88439925 | L47: 11 | M47: =_xlfn.NUMBERVALUE("" & K47 & "",".",",") -> 1.8843992 | O47: =VLOOKUP(C47,statusdetails!$A:$D,4,0) -> STANDBY | P47: =VLOOKUP(F47,equipment!$A:$E,4,0) -> CM05 | Q47: =VLOOKUP(F47,equipment!$A:$E,5,0) -> CM05 - 88
A48: 466129 | B48: 466129 | C48: 1 | D48: 6 | E48: 586 | F48: 41 | G48: 126 | H48: 2025-09-01 11:37:52.237954 | I48: 2025-09-01 18:48:53.245871 | J48: 45901 | K48: 7.18361331027778 | L48: 11 | M48: =_xlfn.NUMBERVALUE("" & K48 & "",".",",") -> 7.1836133 | O48: =VLOOKUP(C48,statusdetails!$A:$D,4,0) -> READY
...

Sheet statusdetails
A1: Id main status | B1: Id type status | C1: Id detail status | D1: Main status | E1: Type status | F1: Detail status
A2: 1 | B2: 6 | C2: 18 | D2: READY | E2: Productivo | F2: En Producción
A3: 1 | B3: 6 | C3: 138 | D3: READY | E3: Productivo | F3: En Producción
A4: 1 | B4: 6 | C4: 139 | D4: READY | E4: Productivo | F4: Traslado Operativo
A5: 1 | B5: 6 | C5: 260 | D5: READY | E5: Productivo | F5: En Producción
A6: 1 | B6: 6 | C6: 261 | D6: READY | E6: Productivo | F6: Traslado Operativo
A7: 1 | B7: 6 | C7: 372 | D7: READY | E7: Productivo | F7: En Producción
A8: 1 | B8: 6 | C8: 373 | D8: READY | E8: Productivo | F8: Traslado Operativo
A9: 1 | B9: 6 | C9: 479 | D9: READY | E9: Productivo | F9: En Producción
A10: 1 | B10: 6 | C10: 480 | D10: READY | E10: Productivo | F10: Traslado Operativo
A11: 1 | B11: 6 | C11: 586 | D11: READY | E11: Productivo | F11: En Producción
A12: 1 | B12: 6 | C12: 587 | D12: READY | E12: Productivo | F12: Traslado Operativo
A13: 1 | B13: 6 | C13: 700 | D13: READY | E13: Productivo | F13: En Producción
... A2639: 5 | B2639: 17 | C2639: 2409 | D2639: OUTOFPLAN | E2639: Programado | F2639: Fuera de plan

Sheet equipment
A1: Id equipment | B1: Fleet type | C1: Fleet category | D1: Equipment | E1: Equipment - ID
A2: 36 | B2: Acarreo en Mina | C2: HD785 | D2: CM401 | E2: CM401 - 36
A3: 31 | B3: Acarreo en Mina | C3: HD785 | D3: CM402 | E3: CM402 - 31
A4: 32 | B4: Acarreo en Mina | C4: HD785 | D4: CM403 | E4: CM403 - 32
A5: 34 | B5: Acarreo en Mina | C5: HD785 | D5: CM404 | E5: CM404 - 34
A6: 35 | B6: Acarreo en Mina | C6: HD785 | D6: CM405 | E6: CM405 - 35
A7: 33 | B7: Acarreo en Mina | C7: HD785 | D7: CM406 | E7: CM406 - 33
A8: 66 | B8: Acarreo en Mina | C8: HD785 | D8: CM407 | E8: CM407 - 66
A9: 67 | B9: Acarreo en Mina | C9: HD785 | D9: SANY1 | E9: SANY1 - 67
A10: 68 | B10: Acarreo en Mina | C10: HD785 | D10: SANY2 | E10: SANY2 - 68
A11: 71 | B11: Acarreo en Mina | C11: SANY | D11: SANY1 | E11: SANY1 - 71
A12: 80 | B12: Acarreo en Mina | C12: SANY | D12: SANY1 | E12: SANY1 - 80
A13: 70 | B13: Acarreo en Mina | C13: SANY | D13: SANY2 | E13: SANY2 - 70
... A59: 39 | B59: Tractor de Orugas | C59: D65 | D59: DZ203 | E59: DZ203 - 39
