Workbook

Sheet Cube
B1: cnt | C1: Real date | D1: Equipment | E1: Fleet category | F1: Fleet type | G1: Main status | H1: Suma de Total Hours | I1: total
C2: 45900 | D2: CF601 | E2: WA900 | F2: Carguio en Mina | G2: OUTOFPLAN | H2: 24
C3: 45901 | D3: CF602 | E3: WA900 | F3: Carguio en Mina | G3: MAINT | H3: 24 | I3: =SUBTOTAL(9,H3:H7) -> 0
C4: 45902 | D4: Ch1 | E4: Chancadora | F4: Chancadoras | G4: MAINT | H4: 1.890824 | I4: 48.296198
C5: 45903 | D5: Ch1 | E5: Chancadora | F5: Chancadoras | G5: READY | H5: 22.109176 | I5: 48.296198
B6: =COUNT(B7:B527) -> 83 | H6: =SUBTOTAL(9,H7:H573)+H573 -> 44.563165
B7: 1 | C7: 45904 | D7: CM01 | E7: SCANIA | F7: Acarreo en Mina | G7: DELAY | H7: 0.29619812
C8: 45905 | D8: CM01 | E8: SCANIA | F8: Acarreo en Mina | G8: MAINT | H8: 1.5449415
C9: 45906 | D9: CM01 | E9: SCANIA | F9: Acarreo en Mina | G9: READY | H9: 12.05774
C10: 45907 | D10: CM01 | E10: SCANIA | F10: Acarreo en Mina | G10: STANDBY | H10: 10.101121
A11: =SUBTOTAL(9,B:B) -> 66 | B11: 1 | C11: 45908 | D11: CM02 | E11: SCANIA | F11: Acarreo en Mina | G11: DELAY | H11: 0.27431882
C12: 45909 | D12: CM02 | E12: SCANIA | F12: Acarreo en Mina | G12: MAINT | H12: 2.2563357
C13: 45910 | D13: CM02 | E13: SCANIA | F13: Acarreo en Mina | G13: READY | H13: 18.516134
C14: 45911 | D14: CM02 | E14: SCANIA | F14: Acarreo en Mina | G14: STANDBY | H14: 2.9532115
B15: 1 | C15: 45912 | D15: CM03 | E15: SCANIA | F15: Acarreo en Mina | G15: DELAY | H15: 0.15786211
C16: 45913 | D16: CM03 | E16: SCANIA | F16: Acarreo en Mina | G16: READY | H16: 20.372129
C17: 45914 | D17: CM03 | E17: SCANIA | F17: Acarreo en Mina | G17: STANDBY | H17: 3.4700088
B18: 1 | C18: 45915 | D18: CM04 | E18: SCANIA | F18: Acarreo en Mina | G18: DELAY | H18: 0.36508239
C19: 45916 | D19: CM04 | E19: SCANIA | F19: Acarreo en Mina | G19: READY | H19: 20.027791
C20: 45917 | D20: CM04 | E20: SCANIA | F20: Acarreo en Mina | G20: STANDBY | H20: 3.6071264
C21: 45918 | D21: CM05 | E21: SCANIA | F21: Acarreo en Mina | G21: MAINT | H21: 9.1473103
C22: 45919 | D22: CM05 | E22: SCANIA | F22: Acarreo en Mina | G22: READY | H22: 10.084449
C23: 45920 | D23: CM05 | E23: SCANIA | F23: Acarreo en Mina | G23: STANDBY | H23: 4.7682403
C24: 45921 | D24: CM06 | E24: SCANIA | F24: Acarreo en Mina | G24: MAINT | H24: 0.78054511
C25: 45922 | D25: CM06 | E25: SCANIA | F25: Acarreo en Mina | G25: READY | H25: 19.733588
C26: 45923 | D26: CM06 | E26: SCANIA | F26: Acarreo en Mina | G26: STANDBY | H26: 3.4858674
C27: 45924 | D27: CM07 | E27: SCANIA | F27: Acarreo en Mina | G27: OUTOFPLAN | H27: 24
C28: 45925 | D28: CM401 | E28: HD785 | F28: Acarreo en Mina | G28: OUTOFPLAN | H28: 24
C29: 45926 | D29: CM402 | E29: HD785 | F29: Acarreo en Mina | G29: OUTOFPLAN | H29: 24
B30: 1 | C30: 45927 | D30: CM403 | E30: HD785 | F30: Acarreo en Mina | G30: DELAY | H30: 2.6900305
C31: 45928 | D31: CM403 | E31: HD785 | F31: Acarreo en Mina | G31: READY | H31: 19.990746
C32: 45929 | D32: CM403 | E32: HD785 | F32: Acarreo en Mina | G32: STANDBY | H32: 1.3192233
B33: 1 | C33: 45930 | D33: CM404 | E33: HD785 | F33: Acarreo en Mina | G33: DELAY | H33: 0.56522871
C34: 45931 | D34: CM404 | E34: HD785 | F34: Acarreo en Mina | G34: MAINT | H34: 0.30919098
C35: 45932 | D35: CM404 | E35: HD785 | F35: Acarreo en Mina | G35: READY | H35: 19.825146
C36: 45933 | D36: CM404 | E36: HD785 | F36: Acarreo en Mina | G36: STANDBY | H36: 3.3004344
B37: 1 | C37: 45934 | D37: CM405 | E37: HD785 | F37: Acarreo en Mina | G37: DELAY | H37: 0.21609605
C38: 45935 | D38: CM405 | E38: HD785 | F38: Acarreo en Mina | G38: READY | H38: 20.629306
C39: 45936 | D39: CM405 | E39: HD785 | F39: Acarreo en Mina | G39: STANDBY | H39: 3.1545984
B40: 1 | C40: 45937 | D40: CM406 | E40: HD785 | F40: Acarreo en Mina | G40: DELAY | H40: 0.47065536
...

Sheet Hoja1
A1: Fecha de inicio | B1: 45901 | C1: Fecha fin | D1: 45904
B2: Horas
A3: DELAY | B3: =+SUMIFS(Cube!H:H,Cube!G:G,Hoja1!A3,Cube!C:C,">="&Hoja1!$B$1,Cube!C:C,"<="&Hoja1!$D$1) -> 0.29619812
A4: MAINT | B4: =+SUMIFS(Cube!H:H,Cube!G:G,Hoja1!A4,Cube!C:C,">="&Hoja1!$B$1,Cube!C:C,"<="&Hoja1!$D$1) -> 25.890824
A5: OUTOFPLAN | B5: =+SUMIFS(Cube!H:H,Cube!G:G,Hoja1!A5,Cube!C:C,">="&Hoja1!$B$1,Cube!C:C,"<="&Hoja1!$D$1) -> 0
A6: READY | B6: =+SUMIFS(Cube!H:H,Cube!G:G,Hoja1!A6,Cube!C:C,">="&Hoja1!$B$1,Cube!C:C,"<="&Hoja1!$D$1) -> 22.109176
A7: STANDBY | B7: =+SUMIFS(Cube!H:H,Cube!G:G,Hoja1!A7,Cube!C:C,">="&Hoja1!$B$1,Cube!C:C,"<="&Hoja1!$D$1) -> 0
A10: Camiones | D10: CM401 | E10: CF601 | F10: EX502 | H10: Cargadores | K10: Excadoras
A11: DELAY | B11: {=SUM(SUMIFS(Cube!H:H,Cube!G:G,Hoja1!A11,Cube!C:C,">="&Hoja1!$B$1,Cube!C:C,"<="&Hoja1!$D$1,Cube!D:D,Hoja1!$D$10:$D$22))} -> 0.29619812 | D11: CM402 | E11: CF602 | F11: EX503 | H11: DELAY | I11: {=SUM(SUMIFS(Cube!H:H,Cube!G:G,Hoja1!A11,Cube!C:C,">="&Hoja1!$B$1,Cube!C:C,"<="&Hoja1!$D$1,Cube!D:D,Hoja1!$E$10:$E$22))} -> 0 | K11: DELAY | L11: {=SUM(SUMIFS(Cube!H:H,Cube!G:G,Hoja1!A11,Cube!C:C,">="&Hoja1!$B$1,Cube!C:C,"<="&Hoja1!$D$1,Cube!D:D,Hoja1!$F$10:$F$22))} -> 0
A12: MAINT | B12: {=SUM(SUMIFS(Cube!H:H,Cube!G:G,Hoja1!A12,Cube!C:C,">="&Hoja1!$B$1,Cube!C:C,"<="&Hoja1!$D$1,Cube!D:D,Hoja1!$D$10:$D$22))} -> 0 | D12: CM403 | H12: MAINT | I12: {=SUM(SUMIFS(Cube!H:H,Cube!G:G,Hoja1!A12,Cube!C:C,">="&Hoja1!$B$1,Cube!C:C,"<="&Hoja1!$D$1,Cube!D:D,Hoja1!$E$10:$E$22))} -> 24 | K12: MAINT | L12: {=SUM(SUMIFS(Cube!H:H,Cube!G:G,Hoja1!A12,Cube!C:C,">="&Hoja1!$B$1,Cube!C:C,"<="&Hoja1!$D$1,Cube!D:D,Hoja1!$F$10:$F$22))} -> 0
A13: OUTOFPLAN | B13: {=SUM(SUMIFS(Cube!H:H,Cube!G:G,Hoja1!A13,Cube!C:C,">="&Hoja1!$B$1,Cube!C:C,"<="&Hoja1!$D$1,Cube!D:D,Hoja1!$D$10:$D$22))} -> 0 | D13: CM404 | H13: OUTOFPLAN | I13: {=SUM(SUMIFS(Cube!H:H,Cube!G:G,Hoja1!A13,Cube!C:C,">="&Hoja1!$B$1,Cube!C:C,"<="&Hoja1!$D$1,Cube!D:D,Hoja1!$E$10:$E$22))} -> 0 | K13: OUTOFPLAN | L13: {=SUM(SUMIFS(Cube!H:H,Cube!G:G,Hoja1!A13,Cube!C:C,">="&Hoja1!$B$1,Cube!C:C,"<="&Hoja1!$D$1,Cube!D:D,Hoja1!$F$10:$F$22))} -> 0
A14: READY | B14: {=SUM(SUMIFS(Cube!H:H,Cube!G:G,Hoja1!A14,Cube!C:C,">="&Hoja1!$B$1,Cube!C:C,"<="&Hoja1!$D$1,Cube!D:D,Hoja1!$D$10:$D$22))} -> 0 | D14: CM405 | H14: READY | I14: {=SUM(SUMIFS(Cube!H:H,Cube!G:G,Hoja1!A14,Cube!C:C,">="&Hoja1!$B$1,Cube!C:C,"<="&Hoja1!$D$1,Cube!D:D,Hoja1!$E$10:$E$22))} -> 0 | K14: READY | L14: {=SUM(SUMIFS(Cube!H:H,Cube!G:G,Hoja1!A14,Cube!C:C,">="&Hoja1!$B$1,Cube!C:C,"<="&Hoja1!$D$1,Cube!D:D,Hoja1!$F$10:$F$22))} -> 0
A15: STANDBY | B15: {=SUM(SUMIFS(Cube!H:H,Cube!G:G,Hoja1!A15,Cube!C:C,">="&Hoja1!$B$1,Cube!C:C,"<="&Hoja1!$D$1,Cube!D:D,Hoja1!$D$10:$D$22))} -> 0 | D15: CM406 | H15: STANDBY | I15: {=SUM(SUMIFS(Cube!H:H,Cube!G:G,Hoja1!A15,Cube!C:C,">="&Hoja1!$B$1,Cube!C:C,"<="&Hoja1!$D$1,Cube!D:D,Hoja1!$E$10:$E$22))} -> 0 | K15: STANDBY | L15: {=SUM(SUMIFS(Cube!H:H,Cube!G:G,Hoja1!A15,Cube!C:C,">="&Hoja1!$B$1,Cube!C:C,"<="&Hoja1!$D$1,Cube!D:D,Hoja1!$F$10:$F$22))} -> 0
D16: CM407
D17: CM01
D18: CM02
D19: CM03
D20: CM04
D21: CM05
D22: CM06
